<robot name="robot2">
  <link name="base_link">
    <inertial>
      <mass value="1.0"/>
      <origin xyz="0 0 0"/>
      <inertia ixx="0.1" iyy="0.1" izz="0.1" ixy="0" ixz="0" iyz="0"/>
    </inertial>
    <visual>
      <geometry>
        <box size="0.3 0.2 0.1"/>
      </geometry>
    </visual>
    <collision>
      <geometry>
        <box size="0.3 0.2 0.1"/>
      </geometry>
    </collision>
  </link>

  <joint name="base_to_wheel_left" type="continuous">
    <parent link="base_link"/>
    <child link="wheel_left"/>
    <origin xyz="-0.15 0.1 0"/>
    <axis xyz="0 1 0"/>
  </joint>

  <joint name="base_to_wheel_right" type="continuous">
    <parent link="base_link"/>
    <child link="wheel_right"/>
    <origin xyz="0.15 0.1 0"/>
    <axis xyz="0 1 0"/>
  </joint>

  <link name="wheel_left"/>
  <link name="wheel_right"/>
</robot>

